Workbook

Sheet 3000 with meanings
B1: level | C1: kelime | D1: anlami | E1: örnek cümle
B2: A1 | C2: above | D2: zf; üzerine, yukarıda, üstünde ,üzerinde s.; yukarıdaki, yukarıda geçen | E2: The birds were flying above the clouds. (Kuşlar bulutların üstünde uçuyorlardı.)
B3: A1 | C3: across | D3: f.; boydan boya geçmek ed.; karşısında zf.;karşıdan karşıya | E3: The hospital is right across the bank. (Hastane bankanın tam karşısında.)
B4: A1 | C4: action | D4: eylem, aksiyon, dava, fiil, davranış | E4: Everyone must take responsibility for their actions. (Herkes davranışlarının sorumluluğunu almalı.)
B5: A1 | C5: activity | D5: etkinlik, faaliyet, işlem, fiil | E5: The club provides a wide variety of activities. (Klüp çok çeşitli aktiviteler sunmaktadır.)
B6: A1 | C6: add | D6: eklemek, ilave etmek, katmak , toplamak | E6: Do you want to add your name to the list? (İsmini listeye eklemek ister misin)
B7: A1 | C7: arm | D7: i.; kol , güç, cephane f.; silahlandırmak , destek olmak | E7: She broke her arm in an accident. (Kazada kolunu kırdı.)
B8: A1 | C8: at | D8: zf.; üzere ed.;üzerinde, -de,-da | E8: I met him at school. (Onunla okulda karşılaştım.)
B9: A1 | C9: away | D9: s.; uzak, zf.; uzakta, | E9: She live 100 m away from here. (Buradan 100 metre uzakta yaşıyor.)
B10: A1 | C10: band | D10: i.; bando, müzik grubu ,bant , orkestra, şerit f.; bantlamak , bağlamak | E10: We bought ticket for the concert of the famous band.(Ünlü müzik grubunun konseri için bilet aldık.)
B11: A1 | C11: become | D11: olmak, haline gelmek | E11: She become a finance manager at a private bank .( Özel bir bankada finans müdürü oldu.)
B12: A1 | C12: behind | D12: s.; gerisindeki, ardındaki zf.; arkadan, geride ed.; ardında, arkasında | E12: The cat is standing just behind the window. (Kedi pencerenin hemen arkasında duruyor.)
... B1462: C1 | C1462: yield | D1462: i.; verim, getiri, mahsul f.; ürün vermek, kazanç sağlamak, boyun eğmek, teslim olmak | E1462: Rich soil yields good crops. (Zengin toprak iyi mahsul verir.)

Sheet Cumleler
B2: İngilizce Sözler: İngilizce Kısa, Anlamlı ve Güzel Sözler
B3: Written by Konuşarak Öğren in İngilizce Dersleri
B5: İngilizce Sözler
B6: Bu yazımızda sevdiklerinize gönderebileceğiniz, durumunuza yazabileceğiniz ve hatta hayatınızda size yol gösterebilecek İngilizce sözleri bulabilirsiniz. Güncellenmiş olan en anlamlı İngilizce sözler; karşınızda. Burada yer alan çeviriler; kolayca anlaşılması için özenle hazırlandı ve doğruluğu tekrar tekrar gözden geçirildi.
B7: Siz de sevdiklerinize İngilizce güzel sözler söylemek istiyorsanız doğru adrestesiniz. Üstelik buradaki içeriğimiz sürekli güncellenecek ve yeni kelimeler eklenecektir.
B8: Bir çok alanda özenle hazırlanmış İngilizce sözler listemizde İngilizce spor sözleri, İngilizce Tumblr sözleri, İngilizce komik ve eğlenceli sözler,İngilizce fotoğraf sözleri, gece ile ilgili İngilizce sözler, İngilizce hayat sözleri, İngilizce anneler günü sözleri, İngilizce kısa sözler, arkadaşlık, umut, özgürlük ile ilgili İngilizce sözler ve ünlü kişilerin İngilizce sözleri başlıklarında ihtiyacınız olan en güzel İngilizce sözlerine göz atabilirsiniz.
B9: Peki sevdiklerinize İngilizce aşk sözleri söylemek ister misiniz? Daha önce hazırladığımız İngilizce aşk sözlerini çevirileriyle birlikte mutlaka incelemelisiniz. İngilizce-Türkçe çevirisiyle hazırlanmış olan aşk sözleri de sürekli güncellenecektir.
B10: İngilizce güzel ve anlamlı sözler listemizdeki başlıkları aşağıdaki tablodan inceleyebilir ve başlığa tıklayarak ilgili bölüme hızlıca ulaşabilirsiniz. Üstelik sözlerimizin yanındaki buton ile İngilizce sözlerin telaffuzlarını da dinleyerek kendinizi geliştirebilirsiniz.
B11: Keyifli okumalar…
B13: İngilizce Kısa Sözler
B14: En güzel İngilizce kısa anlamlı sözler Türkçe açıklamalı aşağıdaki tablomuzda bulabilir, sesli telaffuzlarını dinleyebilir ve Türkçelerini öğrenebilirsiniz.
B15: Where there is love there is life. Aşkın olduğu yerde hayat vardır
... B144: A true friend is the greatest of all blessings: Gerçek arkadaş tüm nimetlerden kıymetlidir. Hard Times will always reveal true friends: Gerçek arkadaşlar zor zamanlarda belli olur. A good friend knows all your best stories. A best friend has lived them with you: İyi bir arkadaş tüm iyi anılarınızı bilir. En iyi arkadaş onları sizinle yaşar.

Sheet oxford 5000
B3: KELIME | C3: SEVIYE | D3: KARISIK TERCUME | E3: YDS TERCUME
B4: abandon | C4: B2 | D4: terk etmek, bırakmak, vazgeçmek, yüzüstü bırakmak | E4: =VLOOKUP(B4,'YDS Karisik'!C:D,2,0) -> bırakmak, terk etmek, vazgeçmek,
B5: ability | C5: A2 | D5: yetenek, beceri, kabiliyet, hüner | E5: =VLOOKUP(B5,'YDS Karisik'!C:D,2,0) -> yetenek, kabiliyet, capability, capacity,
B6: able | C6: A2 | D6: yetenekli, hünerli, yapabilen, becerikli,
B7: abolish | C7: C1 | D7: iptal etmek | E7: =VLOOKUP(B7,'YDS Karisik'!C:D,2,0) -> kaldırmak, feshetmek, cancel
B8: abortion | C8: C1 | D8: kürtaj, bebek aldırma, çocuk düşürme | E8: =VLOOKUP(B8,'YDS Karisik'!C:D,2,0) -> kürtaj
B9: about | C9: A1 | D9: üzere, yaklaşık, hemen hemen,aşağı yukarı, hakkında (ed.)
B10: above | C10: A1 | D10: zf; üzerine, yukarıda, üstünde ,üzerinde s.; yukarıdaki, yukarıda geçen
B11: abroad | C11: B2 | D11: zf.; yurt dışında s.; dışarı, dış ülke , yurt dışı | E11: =VLOOKUP(B11,'YDS Karisik'!C:D,2,0) -> yurt dışına, yurt dışında
B12: absence | C12: C1 | D12: bulunmama, yokluk, olmayış | E12: =VLOOKUP(B12,'YDS Karisik'!C:D,2,0) -> presence,
B13: absent | C13: C1 | D13: 1.yok 2.eksik | E13: =VLOOKUP(B13,'YDS Karisik'!C:D,2,0) -> namevcut, yok, unavailable,
B14: absolute | C14: B2 | D14: i. ;mutlak s.; salt,mutlak, kati, kesin | E14: =VLOOKUP(B14,'YDS Karisik'!C:D,2,0) -> 1) tam, halis, saf, mutlak, pure,
B15: absolutely | C15: B1 | D15: kesinlikle, mutlaka, tamamıyla, muhakkak | E15: =VLOOKUP(B15,'YDS Karisik'!C:D,2,0) -> tamamen, kesinlikle, totally, definitely
B16: absorb | C16: B2 | D16: emmek,içine çekmek, soğurmak, özümsemek, anlamak | E16: =VLOOKUP(B16,'YDS Karisik'!C:D,2,0) -> emmek, soğurmak, suck in, zıt anl.=
B17: abstract | C17: B2 | D17: soyut | E17: =VLOOKUP(B17,'YDS Karisik'!C:D,2,0) -> soyut, conceptual, intangible, zıt anl.=
B18: absurd | C18: C1 | D18: saçma
B19: abundance | C19: C1 | D19: bolluk | E19: =VLOOKUP(B19,'YDS Karisik'!C:D,2,0) -> bolluk, çokluk, zenginlik, copiousness,
B20: abuse | C20: C1 | D20: i.; suistimal, taciz f.; suistimal etmek, kötüye kullanmak, | E20: =VLOOKUP(B20,'YDS Karisik'!C:D,2,0) -> kötüye kullanmak, suiistimal etmek, misuse,
B21: academic | C21: B1 | D21: i.; öğretim görevlisi s.; akademik, bilimsel
B22: academy | C22: C1 | D22: akademi
B23: accelerate | C23: C1 | D23: hızlandırmak | E23: =VLOOKUP(B23,'YDS Karisik'!C:D,2,0) -> hızlan(dır)mak, ivme kazan(dır)mak,
B24: accent | C24: B2 | D24: şive, aksan
B25: accept | C25: A2 | D25: kabul etmek, kabullenmek, onaylamak
B26: acceptable | C26: B2 | D26: kabul edilebilir
B27: acceptance | C27: C1 | D27: kabul
B28: access | C28: B1 | D28: i.; erişme, erişim, giriş f.; erişmek,
B29: accessible | C29: C1 | D29: 1)içine girilebilinir 2)kolay bulunur | E29: =VLOOKUP(B29,'YDS Karisik'!C:D,2,0) -> ulaşılabilir, yararlanılabilir, available,
B30: accident | C30: A2 | D30: kaza , arıza, rastlantı, beklenmedik olay, kazara | E30: =VLOOKUP(B30,'YDS Karisik'!C:D,2,0) -> kaza
B31: accidentally | C31: B2 | D31: kazara | E31: =VLOOKUP(B31,'YDS Karisik'!C:D,2,0) -> kazara, yanlışlıkla, tesadüfen
B32: accommodate | C32: B2 | D32: yerleştirmek | E32: =VLOOKUP(B32,'YDS Karisik'!C:D,2,0) -> 1) yer / yaşam alanı sağlamak, be
B33: accompany | C33: B2 | D33: eşlik etmek, yanında olmak, , arkadaşlık etmek, yoldaşlık etmek | E33: =VLOOKUP(B33,'YDS Karisik'!C:D,2,0) -> eşlik etmek, (bir şey)’in beraberinde
B34: accomplish | C34: B2 | D34: başarıyla tamamlamak, becermek, sonuçlandırmak, üstesinden gelmek
B35: accomplishment | C35: C1 | D35: başarı | E35: =VLOOKUP(B35,'YDS Karisik'!C:D,2,0) -> başarı, üstesinden gelme,
B36: accordance | C36: C1 | D36: uygun
B37: according | C37: A2 | D37: i.; uyma f.; uyarak, uygun olarak, -e göre, birseye bagli olarak
B38: accordingly | C38: C1 | D38: buna göre | E38: =VLOOKUP(B38,'YDS Karisik'!C:D,2,0) -> dolayısıyla, bu nedenle, so,
B39: account | C39: B2 | D39: i.; hesap , hesap verme f.; açıklamak, hesap vermek, saymak
B40: accountability | C40: C1 | D40: Hesap verebilirlik
B41: accountable | C41: C1 | D41: sorumlu
B42: accountant | C42: B2 | D42: Muhasebeci
...

Sheet 3600
B2: Abandon | C2: ebandın | D2: terk etmek | E2: =VLOOKUP(B2,'oxford 5000'!B:C,2,0) -> B2
B3: Ability | C3: ebılıti | D3: yetenek | E3: =VLOOKUP(B3,'oxford 5000'!B:C,2,0) -> A2
B4: Able | C4: eybıl | D4: muktedir | E4: =VLOOKUP(B4,'oxford 5000'!B:C,2,0) -> A2
B5: Aboard | C5: ebord | D5: (bir taşıtın)içinde olmak | E5: =VLOOKUP(B5,'oxford 5000'!B:C,2,0) -> #N/A
B6: About | C6: ebaut | D6: 1.hakkinda 2.yaklaşik olarak | E6: =VLOOKUP(B6,'oxford 5000'!B:C,2,0) -> A1
B7: Above | C7: ebav | D7: yukaridaki | E7: =VLOOKUP(B7,'oxford 5000'!B:C,2,0) -> A1
B8: Abroad | C8: ebrod | D8: yurt dişi | E8: =VLOOKUP(B8,'oxford 5000'!B:C,2,0) -> B2
B9: Absence | C9: ebsıns | D9: yokluk | E9: =VLOOKUP(B9,'oxford 5000'!B:C,2,0) -> C1
B10: Absent | C10: ebsınt | D10: 1.yok 2.eksik | E10: =VLOOKUP(B10,'oxford 5000'!B:C,2,0) -> C1
B11: Absolute | C11: ebsolut | D11: mutlak, kesin | E11: =VLOOKUP(B11,'oxford 5000'!B:C,2,0) -> B2
B12: Absurd | C12: ebzörd | D12: saçma | E12: =VLOOKUP(B12,'oxford 5000'!B:C,2,0) -> C1
B13: Accept | C13: eksept | D13: kabul etmek | E13: =VLOOKUP(B13,'oxford 5000'!B:C,2,0) -> A2
... B3627: What If | C3627: wat if | D3627: ne olurdu.. | E3627: =VLOOKUP(B3627,'oxford 5000'!B:C,2,0) -> #N/A
B3628: What's Its (His/Her) Name | D3628: bilmem kim (birisinin adini unutma) | E3628: =VLOOKUP(B3628,'oxford 5000'!B:C,2,0) -> #N/A
B3629: What's More | C3629: wats mor | D3629: bunun yanisira, üstelik | E3629: =VLOOKUP(B3629,'oxford 5000'!B:C,2,0) -> #N/A
B3630: What's What | C3630: wats wat | D3630: işin önemini bilmek (i know what's what) | E3630: =VLOOKUP(B3630,'oxford 5000'!B:C,2,0) -> #N/A
B3631: Wheel | C3631: wiil | D3631: tekerlek, çark, tekerlekli bir şeyi elle itmek | E3631: =VLOOKUP(B3631,'oxford 5000'!B:C,2,0) -> A2
B3632: Whim | C3632: whim | D3632: kapris | E3632: =VLOOKUP(B3632,'oxford 5000'!B:C,2,0) -> #N/A
B3633: Whisper | C3633: wispır | D3633: fisildamak, fisildaşmak | E3633: =VLOOKUP(B3633,'oxford 5000'!B:C,2,0) -> B2
B3634: Wind Screen | C3634: wind skriin | D3634: araba ön cami | E3634: =VLOOKUP(B3634,'oxford 5000'!B:C,2,0) -> #N/A
B3635: Windpipe | C3635: windpayp | D3635: nefes borusu | E3635: =VLOOKUP(B3635,'oxford 5000'!B:C,2,0) -> #N/A
B3636: Windscreen Wiper | C3636: windskriin way | D3636: silecek | E3636: =VLOOKUP(B3636,'oxford 5000'!B:C,2,0) -> #N/A
B3637: Wing | C3637: wing | D3637: kanat (kuş,uçak)(left wing:sol kesimi destekleyenler | E3637: =VLOOKUP(B3637,'oxford 5000'!B:C,2,0) -> B1
B3638: Wisdom | C3638: wizdım | D3638: akil | E3638: =VLOOKUP(B3638,'oxford 5000'!B:C,2,0) -> B2
B3639: Witch | C3639: wiρ | D3639: cadi | E3639: =VLOOKUP(B3639,'oxford 5000'!B:C,2,0) -> #N/A
B3640: Worship | C3640: wörşip | D3640: 1)tapmak, tapinmak, ibadet 2)hayranlik, saygi | E3640: =VLOOKUP(B3640,'oxford 5000'!B:C,2,0) -> C1
... B3642: Zoom | C3642: zum | D3642: yaklaştirmak | E3642: =VLOOKUP(B3642,'oxford 5000'!B:C,2,0) -> #N/A

Sheet YDS Karisik
B2: a broad range = geniş bir alan / yelpaze | C2: a broad range | D2: geniş bir alan / yelpaze
B3: a case in point = iyi bir örnek | C3: a case in point | D3: iyi bir örnek
B4: a change of air = hava değişimi | C4: a change of air | D4: hava değişimi
B5: a couple of = birkaç, iki üç, a few | C5: a couple of | D5: birkaç, iki üç, a few
B6: a day out in the country = dışarıda kırlarda | C6: a day out in the country | D6: dışarıda kırlarda geçirilen bir gün
B7: a desperate situation = vahim bir durum | C7: a desperate situation | D7: vahim bir durum
B8: a far from pleasant place to live = yaşamak için | C8: a far from pleasant place to live | D8: yaşamak için
B9: iyi / hoş bir yer olmaktan uzak | C9: iyi / hoş bir | D9: bir yer olmaktan uzak
B10: a full recovery = tam bir iyileşme / düzelme | C10: a full recovery | D10: tam bir iyileşme / düzelme
B11: a good many = birçok, hayli, a large number of | C11: a good many | D11: birçok, hayli, a large number of
B12: a great deal (of) = oldukça fazla, çok, a lot, much, | C12: a great deal (of) | D12: oldukça fazla, çok, a lot, much,
B13: zıt anl.= a little, a bit | C13: zıt anl.= a | D13: a little, a bit
B14: a large number (of) = birçok, hayli, a good many, | C14: a large number (of) | D14: birçok, hayli, a good many,
B15: a lot (of) | C15: a lot (of
B16: a major step forward = ileriye doğru büyük bir adım | C16: a major step forward | D16: ileriye doğru büyük bir adım
B17: a matter of time = an meselesi | C17: a matter of time | D17: an meselesi
B18: a number of = çok sayıda, (belli) bir miktar, a lot of, | C18: a number of | D18: çok sayıda, (belli) bir miktar, a lot of,
B19: plenty of
B20: a painful cut in pay = maaşlarda büyük bir kesinti | C20: a painful cut in pay | D20: maaşlarda büyük bir kesinti
B21: a range of = 1) çeşitli, various; 2) bir dizi, a series of | C21: a range of | D21: 1) çeşitli, various; 2) bir dizi, a series of
B22: a series of = bir dizi, a range of | C22: a series of | D22: bir dizi, a range of
B23: a series of measures = bir dizi önlem / tedbir | C23: a series of measures | D23: bir dizi önlem / tedbir
B24: a sociallyminded urban style = sosyal kaygılar | C24: a sociallyminded urban style | D24: sosyal kaygılar
B25: güden bir kentleşme biçimi | C25: güden bir kentleşme | D25: güden bir kentleşme biçimi
B26: a sure sign (of) = (bir şey)’in kesin bir işareti / | C26: a sure sign (of) | D26: (bir şey)’in kesin bir işareti /
B27: göstergesi
B28: a variety of = bir dizi, a range of | C28: a variety of | D28: bir dizi, a range of
B29: a whole range of = her çeşit, her tür, çok çeşitli | C29: a whole range of | D29: her çeşit, her tür, çok çeşitli
B30: a wide range of reasons = çok çeşitli sebepler | C30: a wide range of reasons | D30: çok çeşitli sebepler
B31: A. D. = Milattan / İsa’dan sonra, anno Domini, zıt | C31: A. D. | D31: Milattan / İsa’dan sonra, anno Domini, zıt
B32: anl.= B. C. , before Christ | C32: anl.= B. C | D32: B. C. , before Christ
B33: abandon = bırakmak, terk etmek, vazgeçmek, | C33: abandon | D33: bırakmak, terk etmek, vazgeçmek,
B34: discontinue, stop, zıt anl.= pursue, carry on | C34: discontinue, stop, zıt | D34: pursue, carry on
B35: abandoned = terk edilmiş, boş, (bina için) viran | C35: abandoned | D35: terk edilmiş, boş, (bina için) viran
B36: halde, desolate, zıt anl.= occupied | C36: halde, desolate, zıt | D36: occupied
B37: abandonment = terk etme / edilme, bırak(ıl)ma, | C37: abandonment | D37: terk etme / edilme, bırak(ıl)ma,
B38: desertion
B39: abate = azal(t)mak, hızını kesmek, die away, | C39: abate | D39: azal(t)mak, hızını kesmek, die away,
B40: diminish, zıt anl.= amplify, intensify | C40: diminish, zıt anl | D40: amplify, intensify
B41: abbreviation = kısaltma | C41: abbreviation | D41: kısaltma
...

Sheet 16000
B1: Word | C1: turkish meaning of below words
A2: 1 | B2: (it's well) worth it | C2: buna değer
A3: 2 | B3: a bit more | C3: biraz daha fazla
A4: 3 | B4: a bunch of | C4: bir grup
A5: 4 | B5: a clear conscience | C5: gönül rahatlığı
A6: 5 | B6: a dithering idiot | C6: sarsak
A7: 6 | B7: A Few | C7: az sayıda
A8: 7 | B8: a good deal of | C8: bir damla,birçok
A9: 8 | B9: A Great Many | C9: pek çok , çok fazla
A10: 9 | B10: a leg up | C10: destek,koltuk çıkma
A11: 10 | B11: a little way off | C11: biraz uzakta
A12: 11 | B12: a long way off | C12: çok uzak,çok uzakta
A13: 12 | B13: a modicum of | C13: zerre kadar,az bir miktar
... A16001: 15698 | B16001: wench | C16001: hizmetçi kız

Sheet İdiom
A1: Idioms
A2: sıra | B2: kelime | C2: türkçesi | D2: sıra | E2: kelime | F2: türkçesi
A3: 1 | B3: a bean counter | C3: (aşağılayıcı anlamda) muhasebeci | D3: 248 | E3: huff and puff | F3: burnundan solumak, öfleyip pöflemek
A4: 2 | B4: a bee in one's bonnet | C4: bir konuya kafasını takmak | D4: 249 | E4: I could eat a horse | F4: kurt gibi açım
A5: 3 | B5: a big-head | C5: ukala, bilmiş | D5: 250 | E5: if push comes to shove | F5: iş o noktaya gelirse
A6: 4 | B6: a bit under the weather | C6: kendini kötü hissetmek | D6: 251 | E6: in a black mood | F6: kötü ruh hali
B7: a center of interest | C7: ilgi merkezi | D7: 252 | E7: in a constant state of flux | F7: sürekli değişen, değişmekte
A8: 5 | B8: a chunk of change | C8: büyük/çok para | D8: 253 | E8: in a pinch | F8: gerektiğinde, sıkışınca
A9: 6 | B9: a cog in the machine | C9: çarkın dişlisi, sistemin işlemesini sağlayan küçük bir parça | D9: 254 | E9: in any event | F9: ne olursa olsun, her halükarda
A10: 7 | B10: a cold fish | C10: soguk,arkadaşça olmayan | D10: 255 | E10: in dribs and drabs | F10: azar azar
A11: 8 | B11: a face as long as a fiddle | C11: çok üzgün görünen | D11: 256 | E11: in fine fettle | F11: keyfi yerinde.
A12: 9 | B12: a good turn | C12: bir iyilik: arkadaşça davranış | D12: 257 | E12: in for a penny in for a pound | F12: kaybedecek bir şey yok, battı balık yan gider
A13: 10 | B13: a heart of gold | C13: altın gibi kalbi olmak | D13: 258 | E13: in full swing | F13: en yoğun döneminde, tam faaliyet halinde
A14: 11 | B14: a heavy hitter | C14: ağır top | D14: 259 | E14: in high dudgeon | F14: hiddetli.siniri tepesinde
A15: 12 | B15: a red-letter day | C15: önemli/özel gün | D15: 260 | E15: in high spirits | F15: sevinçli,neşeli
A16: 13 | B16: a shot across the bow | C16: uyarı ateşi,uyarı | D16: 261 | E16: in one fell swoop | F16: bir hamlede.bir çırpıda
A17: 14 | B17: a skeleton in the cupboard | C17: aile sırrı ,kirli çamaşır | D17: 262 | E17: in one's heart of hearts | F17: kalbinin derinliklerinde.tüm kalbiyle
A18: 15 | B18: a whole nother thing | C18: tamamen başka bir şey,tümüyle apayrı bir şey | D18: 263 | E18: in someone's stead | F18: birinin namına, birinin yerine
A19: 16 | B19: abound in\with | C19: (bir yerde) bol olmak, çok olmak. | D19: 264 | E19: in the blink of an eye | F19: göz açıp kapayana kadar
... A55: 47 | B55: be on the warpath | C55: burnundan solumak, küplere binmek | D55: 301 | E55: let in on | F55: birine gizli/herkesin bilmediği bir sırrı açıklamak
B56: be on to someone | C56: (birinin) ne numara çevirdiğini anlamak | D56: 302 | E56: let off the hook | F56: zor durumdan kurtarmak, sorundan kurtarmak
A57: 48 | B57: be out for blood | C57: intikam istemek/aramak | D57: 303 | E57: let out | F57: kaçmasına izin vermek, (bilgi vb) dışarı sızdırmak
A58: 49 | B58: be out of keeping with | C58: (bir şeye) uygun olmamak, garip kaçmak | D58: 304 | E58: let the cat out of the bag | F58: ağzındaki baklayı çıkarmak, bir sırrı açıklamak
A59: 50 | B59: be up and about | C59: tekrar eski haline gelmek, (hastalıktan) kalkmak | D59: 305 | E59: let the dead bury dead | F59: geçmişe sünger çek
A60: 51 | B60: be well in with | C60: arkadaşlık kurmak, insanlarla iyi ilişkiler kurmak | D60: 306 | E60: lie fallow | F60: boş kalmak, (yetenek) (uzun süredir) kullanılmamak
A61: 52 | B61: bear in mind | C61: unutma | D61: 307 | E61: lie low | F61: gizlenmek, saklanmak.
A62: 53 | B62: beat about the bush | C62: bin dereden su getirmek, sözü ağzında gevelemek | D62: 308 | E62: lie through one's teeth | F62: bir ayak üstünde bin yalan söylemek, adamın gözünün içine baka baka yalan söylemek
A63: 54 | B63: bide one's time | C63: (bir iş için) uygun zamanı beklemek | D63: 309 | E63: like a bear with sore head | F63: sinirli,huysuz,sol tarafından kalkmış
A64: 55 | B64: big-shot | C64: önemli kimse,kodoman | D64: 310 | E64: lion's share of something | F64: bir şeyin aslan payı
A65: 56 | B65: bit off | C65: bir tahtası eksik, hafif kaçık | D65: 311 | E65: live on the edge | F65: hayatı uçlarda yaşamak
B66: black sheep of the family | C66: ailenin yüz karası | D66: 312 | E66: live to a ripe old age | F66: iyice yaşlanana kadar yaşamak, çok uzun yaşamak
A67: 57 | B67: blow a gasket | C67: öfkelenmek, deliye dönmek | D67: 313 | E67: live up to all the hype | F67: yazıldığı/gösterildiği gibi çıkmak, beklenildiği gibi olmak
A68: 58 | B68: blow off some steam | C68: içini döküp rahatlamak | D68: 314 | E68: look down in the dumps | F68: çok neşesiz olmak,karadeniz'de gemileri batmış gibi durmak
A69: 59 | B69: blow your own trumpet | C69: (böbür böbür) böbürlenmek | D69: 315 | E69: look for a needle in a haystack | F69: samanlıkta iğne aramak
A70: 60 | B70: bone chilling | C70: tüyler ürpertici,korkutucu | D70: 316 | E70: look high and low (for someone or something) | F70: bakmadık yer bırakmamak,didik didik aramak
A71: 265 | B71: bone of contention | C71: ihtilaf konusu. anlaşmazlık sebebi | D71: 317 | E71: lose no time in doing something | F71: hemen/hiç vakit kaybetmeden (bir işe girişmek)
A72: 61 | B72: bottom line | C72: uzun lafın kısası,(asıl) önemli olan,sonuç | D72: 318 | E72: lose-lose situation | F72: kazanma ihtimali olmayan durum
A73: 62 | B73: bowl over | C73: ağzı bir karış açık kalmak, vurup devirmek | D73: 319 | E73: make a clean breast of | F73: itiraf etmek, içini boşaltmak, içini dökmek.
A74: 63 | B74: break it to…. | C74: birine kötü bir haber vermek | D74: 320 | E74: make a fool of | F74: rezil etmek,aptal durumuna düşürmek
A75: 64 | B75: bring something upon oneself | C75: kendi başına (dert) açmak | D75: 321 | E75: make a lucky guess | F75: şanslı bir tahmin yapmak
...

Sheet phrasal verb
A1: Phrasal verbs
A2: word | B2: meaning | C2: word | D2: meaning | E2: word | F2: meaning
A3: abide by | B3: ..-e uymak, -e riayet etmek. | C3: go by | D3: geçmek,göre hareket etmek, kılavuz saymak | E3: ride out | F3: sağ salim çıkmak
A4: account for | B4: hesap vermek, açıklamak | C4: go down | D4: inmek,(iş vb) batmak | E4: ride up | F4: yukarı çıkmak
A5: act on | B5: etkilemek | C5: go down on | D5: oral seks yapmak | E5: rig out | F5: süslenip püslenmek
A6: act out | B6: (rol) canlandırmak | C6: go for | D6: tercih etmek,dışarı çıkmak,hoşlanmak | E6: rig up | F6: uyduruvermek
A7: act up | B7: yaramazlık yapmak,gösteriş yapmak. | C7: go in | D7: içeriye girmek,içeri girmek | E7: rile up | F7: sinirlendirmek
A8: add up | B8: toplamak,makul olmak, akla yakın olmak. | C8: go in for | D8: bir şeyi yapmaktan hoşlanmak,bir şeyin meraklısı olmak | E8: ring off | F8: telefonu kapamak
A9: add up to | B9: -e varmak, (bir yekûn) tutmak.anlamına gelmek: | C9: go into | D9: girmek, girmek (konuşmaya-tartışmaya) | E9: rip off | F9: kazık atmak, kazıklamak
A10: after careful thought | B10: iyice düşündükten sonra | C10: go loco | D10: delirmek, balatayı yakmak | E10: roll away | F10: yuvarlanarak ilerlemek
A11: after math | B11: kötü sonuç,kötü yan etki | C11: go off | D11: .. -den hoşlanmamaya başlamak.patlamak. geçmek (bir olay belirli bir şekilde) | E11: roll on | F11: yuvarlanmak
A12: all but | B12: hemen hemen,neredeyse | C12: go off on one | D12: kendini kaybetmek, kontrolü kaybetmek | E12: roll out | F12: sunmak,ilk kez görücüye çıkarılmak
A13: amp up | B13: güçlendirmek, arttırmak | C13: go on | D13: Devam etmek,Olmak, meydana gelmek | E13: roll up | F13: sıvamak,toplanmak
... A449: go away | B449: gitmek, ayrılmak. | C449: rely upon | D449: bel bağlamak,güvenmek | E449: hollow out | F449: çukur açmak.kazmak
A450: go back | B450: Geri dönmek | C450: remark on someone | D450: biri hakkında yorumda bulunmak
A451: go back over | B451: tekrar/yeniden gözden geçirmek/incelemek | C451: rev up | D451: hızlandırmak
A452: go behind | B452: peşine takılıp gitmek | C452: ride off | D452: atını sürerek gitmek

Sheet conjunction
A1: Conjunction
A2: word | B2: meaning | C2: word | D2: meaning | E2: word | F2: meaning
A3: according as | B3: .-dikçe, tıpkı ,,-diği gibi | C3: except | D3: haricinde,dışında | E3: on the contrary | F3: aksine
A4: accordingly | B4: bu doğrultuda,buna göre | C4: except if | D4: . -mesinin dışında | E4: on the grounds that | F4: ...-e dayanarak
A5: actually | B5: aslında, gerçekten | C5: for fear that | D5: korkusu ile | E5: on the other hand | F5: öte yandan
A6: additionally | B6: ek olarak ,ayrıca | C6: for that reason that | D6: işte bu sebepten ötürü | E6: on the pretext that | F6: bahanesiyle
A7: after | B7: ...-den sonra, ardından | C7: for the reason that | D7: sebebiyle | E7: once | F7: bir zamanlar,bir kere,-ir -mez
A8: after which | B8: ..-mesinden sonra.-den sonra | C8: from which | D8: oradan , -den | E8: one would think that | F8: güya
A9: afterwards | B9: ardından | C9: furthermore | D9: bundan başka, ayrıca. | E9: one would wish that | F9: gönül ister ki
A10: Albeit | B10: ... de olsa:gerçi,hernekadar,isede | C10: given that | D10: tahminen, farz edelim ki | E10: only if | F10: tek şartla
A11: also | B11: ayrıca,hemde -de, -da | C11: hence | D11: bu yüzden | E11: or | F11: veya, ya da, aksi takdirde
A12: although yet | B12: her ne kadar olsa da | C12: however | D12: ancak,fakat,her nasılsa | E12: or else | F12: aksi takdirde
A13: although/though | B13: ….-e rağmen/rağmen | C13: however much | D13: ne kadar olursa olsun | E13: otherwise | F13: aksi takdirde
... A54: even when | B54: ...-dığı zaman bile | C54: on condition that | D54: koşuluyla,şartıyla | E54: yet more | F54: hatta bundan daha fazla, hatta

Sheet prepositional phrases
A1: Prepositional phrases
A2: word | B2: meaning | C2: word | D2: meaning | E2: word | F2: meaning
A3: a diversity of | B3: birçok farklı | C3: in advance of | D3: öncesinde,-in önünde | E3: in view of | F3: ..den dolayı, göz önüne alarak
A4: a good deal of | B4: birçok | C4: in aid of | D4: menfaatine, -e yardım için. | E4: in wake of | F4: izini takip ederek,peşinde
A5: a great deal of | B5: ..çok, bir hayli | C5: in an attempt to | D5: .mak için. mek için, amacıyla | E5: including | F5: dahil
A6: a large amount of | B6: çok miktarda | C6: in an effort to | D6: amacıyla, mak için, mek için | E6: inside of | F6: dahilinde, -in içinde
A7: a large quantity of | B7: çok miktarda | C7: in and around | D7: içinde ve çevresinde | E7: instead of | F7: ...ın yerine
A8: a number of | B8: birkaç, bir çok | C8: in anticipation of | D8: bir şeyin gerçekleşebileceği düşüncesiyle | E8: irrespective of | F8: ...e bakılmaksızın
A9: a range of | B9: bir dizi | C9: in between | D9: arasında, aralarında | E9: just like | F9: gibi
A10: a variety of | B10: bir çok farklı | C10: in case of | D10: ...ın durumunda | E10: less than | F10: ...den az
A11: a whole bunch of | B11: bir sürü | C11: in commemoration of | D11: anısına | E11: mindless of | F11: .e aldırış etmeyen
A12: a wide range of | B12: bir çok farklı | C12: in common with | D12: ile ortak olarak | E12: more than | F12: ...den fazla
A13: according to | B13: ...e göre | C13: in company with | D13: ile beraber, birlikte. | E13: next to | F13: .-in yanında, -e bitişik; -in yakınındaki.
... A34: as per | B34: gereğince,uyarınca, göre | C34: in particular | D34: özellikle, bilhassa | E34: opposite to | F34: . -e karşı,-e muhalif
C35: in place of | D35: ...ın yerine | E35: other than | F35: ..den başka
A36: as regards | B36: ..gelince, ile ilgili | C36: in point of | D36: hususunda, bakımından | E36: out of keeping with | F36: ile uyumsuz olarak
A37: as such in | B37: . -de olduğu gibi | C37: in preference to | D37: . -e tercihen,öncelikle | E37: outside of | F37: dışında, haricinde
A38: as to | B38: ...e dair, -ile ilgili | C38: in prospect of | D38: varsayımıyla | E38: over and above | F38: yanında,üstelik,-den ayrı olarak, -den başka.
A39: as to whether | B39: olup olmadığına gelince, olup olmadığı konusunda | C39: in pursuance of | D39: yerine getirirken, peşinde koşarken, gerçekleştirmeye çalışırken | E39: owing to | F39: ...den dolayı
A40: as well | B40: ...de , -da | C40: in pursuant of | D40: uygun olarak,göre | E40: partial to | F40: meyilli, -e taraftar
A41: as well as | B41: ...ve de, yanısıra,yanısıra | C41: in pursuit of | D41: peşinde, arayışta | E41: pertaining to | F41: ile ilgili
A42: as with | B42: ...-da olduğu gibi | C42: in recognition of | D42: bakımından, tanınmasıyla | E42: prior to | F42: ...den önce
A43: as yet | B43: şimdiye kadar, henüz | C43: in reference to | D43: ..-e dair, -e ilişkin,nazaran | E43: pursuant to | F43: .-e göre.-e uygun olarak
A44: aside from | B44: dışında, -den başka | C44: in regard to | D44: .-e gelince. -e göre | E44: ranging from | F44: . -den tutun da, -den -e uzanan
A45: astern of | B45: .-den arkaya,arkada | C45: in relation to | D45: hakkında. - e ilişkin olarak | E45: rather than | F45: ..den ziyade
A46: at least | B46: en azından, hiç olmazsa | C46: in respect of | D46: dair,hakkında,hususunda | E46: regardless of | F46: ...e bakılmaksızın
A47: at odd | B47: arası açık olmak | C47: in response to | D47: ...e karşılık olarak | E47: related to | F47: ile ilgili
... A83: in accordance with | B83: ..e paralel olarak | C83: in trust | D83: gözetiminde | E83: within the scope of | F83: kapsamında, çerçevesinde
A84: in addition to | B84: ...e ilaveten

Sheet oxford 3000
C2: a | D2: (herhangi) bir | E2: a book, a car , a movie (bir kitap, bir araba, bir film)
B3: * | C3: abandon | D3: terk etmek, bırakmak, vazgeçmek, yüzüstü bırakmak | E3: The children have been abandoned by their mother. (Çocuklar anneleri tarafından terk edildi.)
C4: abandoned | D4: terk edilmiş, terk, Vazgeçilen | E4: Sen de kendini terk edilmiş hissetmişsin. You felt they'd abandoned you.
C5: ability | D5: yetenek, beceri, kabiliyet, hüner | E5: She has some musical ability. (Onun biraz müzik yeteneği var.)
C6: able | D6: yetenekli, hünerli, yapabilen, becerikli, | E6: You must be able to speak German for this job. (Bu iş için Almanca konuşuyor olabilmelisin.)
C7: unable | D7: aciz, yapamaz, gücü yetmez | E7: I tried to contact him but was unable to. (Onunla irtibat kurmaya çalıştım ama olmadı.)
C8: about | D8: üzere, yaklaşık, hemen hemen,aşağı yukarı, hakkında (ed.) | E8: I was very sorry to hear about your sister. (Kardeşin hakkında duyduklarıma çok üzüldüm.)
C9: above | D9: zf; üzerine, yukarıda, üstünde ,üzerinde s.; yukarıdaki, yukarıda geçen | E9: The birds were flying above the clouds. (Kuşlar bulutların üstünde uçuyorlardı.)
C10: abroad | D10: zf.; yurt dışında s.; dışarı, dış ülke , yurt dışı | E10: She worked abroad for a year. ( Bir yıl yurt dışında yaşadı.)
C11: absence | D11: bulunmama, yokluk, olmayış | E11: They didn’t notice his absence. (Onun yokluğunu fark etmediler.)
C12: absent | D12: yok, bulunmuyor, olmama | E12: Typical human behavior is now entirely absent. *İnsana özgü davranışlar, artık tamamen yok.
B13: * | C13: absolute | D13: i. ;mutlak s.; salt,mutlak, kati, kesin | E13: I want absolute silence during the lesson. (Ders süresince mutlak sessizlik istiyorum.)
C14: absolutely | D14: kesinlikle, mutlaka, tamamıyla, muhakkak | E14: It is absolutely an extraordinary situation. (Bu kesinlikle olağanüstü bir durum.)
B15: * | C15: absorb | D15: emmek,içine çekmek, soğurmak, özümsemek, anlamak | E15: Plants absorb oxygen. (Bitkiler oksijen emer.)
B16: * | C16: abuse | D16: i.; suistimal, taciz f.; suistimal etmek, kötüye kullanmak, | E16: She suffered years of physical abuse. (Yıllarca fiziksel tacize uğradı.)
C17: academic | D17: i.; öğretim görevlisi s.; akademik, bilimsel | E17: The new academic year starts in October. (Yeni akademik yıl ekim ayında başlıyor.)
C18: accent | D18: aksan, vurgu, şive | E18: She spoke English with an accent.
C19: accept | D19: kabul etmek, kabullenmek, onaylamak | E19: She has decided not to accept the job. ( İşi kabul etmemeye karar verdi.)
C20: acceptable | D20: kabul edilebilir acceptable, reasonable, palatable, admissible | E20: Not an acceptable mistake. Kabul edilebilir bir hata değil.
B21: * | C21: access | D21: i.; erişme, erişim, giriş f.; erişmek, | E21: You need a password to access the confidential information. (Gizli bilgilere erişmek için bir şifren olması gerek.)
C22: accident | D22: kaza , arıza, rastlantı, beklenmedik olay, kazara | E22: The accident happened at 5 a.m. (Kaza sabah saat 5’te oldu.)
C23: by accident | D23: kaza ile | E23: We met by accident at the airport.
C24: accidental | D24: kaza sonucu | E24: There would be the mandatory accidental damage insurance. zorunlu kaza sonucu hasar sigortası olacaktı.
C25: accidentally | D25: yanlışlıkla **inadvertently, mistakenly, inadvertent, erroneously | E25: I accidentally grabbed your book. Yanlışlıkla senin kitabını almışım.
C26: accompany | D26: eşlik etmek, yanında olmak, , arkadaşlık etmek, yoldaşlık etmek | E26: Her husband accompanied her on the trip. (Gezide kocası ona eşlik etti.)
C27: according | D27: i.; uyma f.; uyarak, uygun olarak, -e göre, birseye bagli olarak | E27: Everything went according to his instructions. (Her şey onun talimatlarına uygun olarak ilerledi.)
C28: account | D28: i.; hesap , hesap verme f.; açıklamak, hesap vermek, saymak | E28: I don’t have a bank account. (Banka hesabım yok.)
B29: * | C29: accurate | D29: kesin, doğru, tam, hatasız, dakik | E29: This watch is not very accurate. (Bu saat çok doğru değil.)
C30: accurately | D30: doğru *right, true, correct, towards, correctly, | E30: Science can predict accurately when a new moon rises. Bilim yeni ay doğumunu tam doğru olarak tahmin edebilir.
B31: * | C31: accuse | D31: suçlamak, suçlamada bulunmak, itham etmek | E31: He accused him of lying. ( Onu yalan söylemekle suçladı.)
C32: achieve | D32: başarmak, elde etmek, ulaşmak, üstesinden gelmek | E32: He had finally achieved great success. (Sonunda büyük başarı elde etti.)
C33: achievement | D33: başarı, başarma, elde etme,kazanım | E33: It was a remarkable achievement for such a young student. (Bu, böylesine genç bir öğrenci için olağanüstü bir başarıydı.)
C34: acid | D34: i.; asit, ekşime s.; ekşi | E34: Acid can damage things. (Asit zarar verebilir.)
B35: * | C35: acknowledge | D35: kabul etmek, kabullenmek, tasdik etmek, beyan etmek | E35: It is generally acknowledged to be wrong. (Bu genel olarak yanlış olarak kabul edilir.)
B36: * | C36: acquire | D36: elde etmek, edinmek, kazanmak, sahip olmak | E36: She has acquired a good knowledge of History. (Tarih konusunda iyi derecede bilgi sahibi oldu.)
C37: across | D37: f.; boydan boya geçmek ed.; karşısında zf.;karşıdan karşıya | E37: The hospital is right across the bank. (Hastane bankanın tam karşısında.)
C38: act | D38: f.; davranmak, hareket etmek, rol oynamak, yalandan yapmak i.; yasa, eylem | E38: Don’t act like sorry. (Üzgünmüş gibi davranma.)
C39: action | D39: eylem, aksiyon, dava, fiil, davranış | E39: Everyone must take responsibility for their actions. (Herkes davranışlarının sorumluluğunu almalı.)
C40: take action | D40: #N/A | E40: #N/A
C41: active | D41: etkin, faal, aktif, çalışkan | E41: She takes an active part in this project. (Bu projede aktif rol alıyor.)
...

Sheet 3000
A2: 1 | C2: 1- a
A3: 2 | C3: (herhangi) bir
A4: 3 | C4: a book, a car , a movie (bir kitap, bir araba, bir film)
A5: 4
A6: 5 | B6: * | C6: 2-abandon ; (fiil)
A7: 6 | C7: terk etmek, bırakmak, vazgeçmek, yüzüstü bırakmak
A8: 7 | C8: The children have been abandoned by their mother. (Çocuklar anneleri tarafından terk edildi.)
A9: 8
A10: 9 | C10: 3-ability; (isim)
A11: 10 | C11: yetenek, beceri, kabiliyet, hüner
A12: 11 | C12: She has some musical ability. (Onun biraz müzik yeteneği var.)
A13: 12
A14: 13 | C14: 4-able; (sıfat)
A15: 14 | C15: yetenekli, hünerli, yapabilen, becerikli,
A16: 15 | C16: You must be able to speak German for this job. (Bu iş için Almanca konuşuyor olabilmelisin.)
A17: 16
A18: 17 | B18: * | C18: 5-abortion; (isim)
A19: 18 | C19: kürtaj, bebek aldırma,çocuk düşürme
A20: 19 | C20: She decided to have an abortion. (O, kürtaj yaptırmaya karar verdi.)
A21: 20 | C21: a woman’s right to abortion
A22: 21 | C22: the country's strict abortion laws
A23: 22 | C23: I've always been anti-abortion.
A24: 23
A25: 24 | C25: 6- about; (zarf, edat)
A26: 25 | C26: üzere, yaklaşık, hemen hemen,aşağı yukarı, hakkında (ed.)
A27: 26 | C27: I was very sorry to hear about your sister. (Kardeşin hakkında duyduklarıma çok üzüldüm.)
A28: 27
A29: 28 | C29: 7- above; (zarf, sıfat)
A30: 29 | C30: zf; üzerine, yukarıda, üstünde ,üzerinde s.; yukarıdaki, yukarıda geçen
A31: 30 | C31: The birds were flying above the clouds. (Kuşlar bulutların üstünde uçuyorlardı.)
A32: 31
A33: 32 | C33: 8- abroad; zarf, sıfat) ---aboard: gemi, ucak vs icinde
A34: 33 | C34: zf.; yurt dışında s.; dışarı, dış ülke , yurt dışı
A35: 34 | C35: She worked abroad for a year. ( Bir yıl yurt dışında yaşadı.)
A36: 35
A37: 36 | C37: 9- absence; (isim)
A38: 37 | C38: bulunmama, yokluk, olmayış
A39: 38 | C39: They didn’t notice his absence. (Onun yokluğunu fark etmediler.)
A40: 39
A41: 40 | B41: * | C41: 10) absolute; (isim, sıfat)
...

Sheet Rating
B4: the | C4: 1
B5: be | C5: 2
B6: and | C6: 3
B7: of | C7: 4
B8: a | C8: 5
B9: in | C9: 6
B10: to | C10: 7
B11: have | C11: 8
B12: to | C12: 9
B13: it | C13: 10
B14: I | C14: 11
B15: that | C15: 12
... B494: arm | C494: 492
B495: TRUE | C495: 493
B496: federal | C496: 494
B497: break | C497: 495
B498: better | C498: 496
B499: difference | C499: 497
B500: thank | C500: 498
B501: receive | C501: 499
B502: value | C502: 500
B503: international | C503: 501
B504: building | C504: 502
B505: action | C505: 503
B506: full | C506: 504
B507: model | C507: 505
... B2649: aggressive | C2649: 2538
B2650: FALSE | C2650: 2539
B2651: intention | C2651: 2540
B2652: channel | C2652: 2541
B2653: extreme | C2653: 2542
B2654: tube | C2654: 2543
B2655: drawing | C2655: 2544
B2656: protein | C2656: 2545
B2657: quit | C2657: 2546
B2658: absence | C2658: 2547
B2659: roll | C2659: 2548
B2660: Latin | C2660: 2549
B2661: rapidly | C2661: 2550
B2662: jail | C2662: 2551
...
